<?xml version='1.0' encoding='utf-8'?>
<robot name="UF_ROBOT">
  <!-- Insert at the beginning of xarm_device_macro.xacro -->
  <material name="Black">
    <color rgba="0.0 0.0 0.0 1.0" />
  </material>
  <material name="Red">
    <color rgba="0.8 0.0 0.0 1.0" />
  </material>
  <material name="White">
    <color rgba="1.0 1.0 1.0 1.0" />
  </material>
  <material name="Silver">
    <color rgba="0.753 0.753 0.753 1.0" />
  </material>
  <link name="world" />
  <joint name="world_joint" type="fixed">
    <parent link="world" />
    <child link="link_base" />
    <origin rpy="0 0 0" xyz="0 0 0" />
  </joint>
  <ros2_control name="uf_robot_hardware/UFRobotSystemHardware" type="system">
    <hardware>
      <plugin>uf_robot_hardware/UFRobotSystemHardware</plugin>
      <param name="hw_ns">xarm</param>
      <param name="velocity_control">False</param>
      <param name="prefix">P</param>
      <param name="robot_ip">R</param>
      <param name="report_type">normal</param>
      <param name="dof">7</param>
      <param name="baud_checkset">True</param>
      <param name="default_gripper_baud">2000000</param>
      <param name="robot_type">xarm</param>
      <param name="add_gripper">False</param>
      <param name="add_bio_gripper">False</param>
    </hardware>
    <joint name="joint1">
      <command_interface name="position">
        <param name="min">-6.283185307179586</param>
        <param name="max">6.283185307179586</param>
      </command_interface>
      <command_interface name="velocity">
        <param name="min">-3.14</param>
        <param name="max">3.14</param>
      </command_interface>
      <state_interface name="position" />
      <state_interface name="velocity" />
      <!-- <state_interface name="effort"/> -->
    </joint>
    <joint name="joint2">
      <command_interface name="position">
        <param name="min">-2.059</param>
        <param name="max">2.0944</param>
      </command_interface>
      <command_interface name="velocity">
        <param name="min">-3.14</param>
        <param name="max">3.14</param>
      </command_interface>
      <state_interface name="position" />
      <state_interface name="velocity" />
      <!-- <state_interface name="effort"/> -->
    </joint>
    <joint name="joint3">
      <command_interface name="position">
        <param name="min">-6.283185307179586</param>
        <param name="max">6.283185307179586</param>
      </command_interface>
      <command_interface name="velocity">
        <param name="min">-3.14</param>
        <param name="max">3.14</param>
      </command_interface>
      <state_interface name="position" />
      <state_interface name="velocity" />
      <!-- <state_interface name="effort"/> -->
    </joint>
    <joint name="joint4">
      <command_interface name="position">
        <param name="min">-0.19198</param>
        <param name="max">3.927</param>
      </command_interface>
      <command_interface name="velocity">
        <param name="min">-3.14</param>
        <param name="max">3.14</param>
      </command_interface>
      <state_interface name="position" />
      <state_interface name="velocity" />
      <!-- <state_interface name="effort"/> -->
    </joint>
    <joint name="joint5">
      <command_interface name="position">
        <param name="min">-6.283185307179586</param>
        <param name="max">6.283185307179586</param>
      </command_interface>
      <command_interface name="velocity">
        <param name="min">-3.14</param>
        <param name="max">3.14</param>
      </command_interface>
      <state_interface name="position" />
      <state_interface name="velocity" />
      <!-- <state_interface name="effort"/> -->
    </joint>
    <joint name="joint6">
      <command_interface name="position">
        <param name="min">-1.69297</param>
        <param name="max">3.141592653589793</param>
      </command_interface>
      <command_interface name="velocity">
        <param name="min">-3.14</param>
        <param name="max">3.14</param>
      </command_interface>
      <state_interface name="position" />
      <state_interface name="velocity" />
      <!-- <state_interface name="effort"/> -->
    </joint>
    <joint name="joint7">
      <command_interface name="position">
        <param name="min">-6.283185307179586</param>
        <param name="max">6.283185307179586</param>
      </command_interface>
      <command_interface name="velocity">
        <param name="min">-3.14</param>
        <param name="max">3.14</param>
      </command_interface>
      <state_interface name="position" />
      <state_interface name="velocity" />
      <!-- <state_interface name="effort"/> -->
    </joint>
  </ros2_control>
  <link name="link_base">
    <inertial>
      <origin rpy="0 0 0" xyz="0.0 0.0 0.05" />
      <mass value="2.971" />
      <inertia ixx="0.010264436627670627" ixy="0.00041128200234879624" ixz="-0.002103714655133475" iyy="0.012675966958760559" iyz="0.0009066052328470121" izz="0.006751815235557161" />
    </inertial>
    <visual>
      <geometry>
        <mesh filename="link_base.stl" />
      </geometry>
      <origin rpy="0 0 0" xyz="0 0 0" />
      <material name="White" />
    </visual>
    <collision>
      <geometry>
        <mesh filename="link_base.stl" />
      </geometry>
      <origin rpy="0 0 0" xyz="0 0 0" />
    </collision>
  </link>
  <link name="link1">
    <inertial>
      <origin rpy="0 0 0" xyz="0.00013 0.0301 -0.012" />
      <mass value="2.46" />
      <inertia ixx="0.00587683879093199" ixy="-1.630705289672544e-05" ixz="5.292821158690176e-06" iyy="0.005118906801007557" iyz="-0.0009019772795969772" izz="0.003425259798488665" />
    </inertial>
    <visual>
      <geometry>
        <mesh filename="link1.stl" />
      </geometry>
      <origin rpy="0 0 0" xyz="0 0 0" />
      <material name="White" />
    </visual>
    <collision>
      <geometry>
        <mesh filename="link1.stl" />
      </geometry>
      <origin rpy="0 0 0" xyz="0 0 0" />
    </collision>
  </link>
  <joint name="joint1" type="revolute">
    <origin rpy="0 0 0" xyz="0 0 0.267" />
    <parent link="link_base" />
    <child link="link1" />
    <axis xyz="0 0 1" />
    <limit effort="50" lower="-6.283185307179586" upper="6.283185307179586" velocity="3.14" />
    <dynamics damping="10" friction="1" />
  </joint>
  <link name="link2">
    <inertial>
      <origin rpy="0 0 0" xyz="0.0002 -0.1296 0.0169" />
      <mass value="1.916" />
      <inertia ixx="0.009840284858212948" ixy="1.5797517388978062e-06" ixz="5.699818084537186e-06" iyy="0.00392090075976458" iyz="-0.0032513156554307117" izz="0.007755923918673087" />
    </inertial>
    <visual>
      <geometry>
        <mesh filename="link2.stl" />
      </geometry>
      <origin rpy="0 0 0" xyz="0 0 0" />
      <material name="White" />
    </visual>
    <collision>
      <geometry>
        <mesh filename="link2.stl" />
      </geometry>
      <origin rpy="0 0 0" xyz="0 0 0" />
    </collision>
  </link>
  <joint name="joint2" type="revolute">
    <origin rpy="-1.5708 0 0" xyz="0 0 0" />
    <parent link="link1" />
    <child link="link2" />
    <axis xyz="0 0 1" />
    <limit effort="50" lower="-2.059" upper="2.0944" velocity="3.14" />
    <dynamics damping="10" friction="1" />
  </joint>
  <link name="link3">
    <inertial>
      <origin rpy="0 0 0" xyz="0.04676 -0.0253 -0.00746" />
      <mass value="1.69" />
      <inertia ixx="0.0032076783861319656" ixy="0.00031810126350485254" ixz="-0.0006029760727583471" iyy="0.00272829316974913" iyz="0.0003495874809253494" izz="0.0027464176280290542" />
    </inertial>
    <visual>
      <geometry>
        <mesh filename="link3.stl" />
      </geometry>
      <origin rpy="0 0 0" xyz="0 0 0" />
      <material name="White" />
    </visual>
    <collision>
      <geometry>
        <mesh filename="link3.stl" />
      </geometry>
      <origin rpy="0 0 0" xyz="0 0 0" />
    </collision>
  </link>
  <joint name="joint3" type="revolute">
    <origin rpy="1.5708 0 0" xyz="0 -0.293 0" />
    <parent link="link2" />
    <child link="link3" />
    <axis xyz="0 0 1" />
    <limit effort="30" lower="-6.283185307179586" upper="6.283185307179586" velocity="3.14" />
    <dynamics damping="5" friction="1" />
  </joint>
  <link name="link4">
    <inertial>
      <origin rpy="0 0 0" xyz="0.07066 -0.1166 0.0117" />
      <mass value="1.774" />
      <inertia ixx="0.006049618391337078" ixy="0.0014085163472117666" ixz="0.0009054703920319647" iyy="0.003695136498928716" iyz="-0.001810216555677804" izz="0.005580606033933638" />
    </inertial>
    <visual>
      <geometry>
        <mesh filename="link4.stl" />
      </geometry>
      <origin rpy="0 0 0" xyz="0 0 0" />
      <material name="White" />
    </visual>
    <collision>
      <geometry>
        <mesh filename="link4.stl" />
      </geometry>
      <origin rpy="0 0 0" xyz="0 0 0" />
    </collision>
  </link>
  <joint name="joint4" type="revolute">
    <origin rpy="1.5708 0 0" xyz="0.0525 0 0" />
    <parent link="link3" />
    <child link="link4" />
    <axis xyz="0 0 1" />
    <limit effort="30" lower="-0.19198" upper="3.927" velocity="3.14" />
    <dynamics damping="5" friction="1" />
  </joint>
  <link name="link5">
    <inertial>
      <origin rpy="0 0 0" xyz="-0.0003 0.0156 -0.0253" />
      <mass value="1.357" />
      <inertia ixx="0.005495269294857229" ixy="1.55372029084299e-05" ixz="-3.7925698704839803e-07" iyy="0.0051162692569870485" iyz="-0.00022747196849200939" izz="0.0014002702416117548" />
    </inertial>
    <visual>
      <geometry>
        <mesh filename="link5.stl" />
      </geometry>
      <origin rpy="0 0 0" xyz="0 0 0" />
      <material name="White" />
    </visual>
    <collision>
      <geometry>
        <mesh filename="link5.stl" />
      </geometry>
      <origin rpy="0 0 0" xyz="0 0 0" />
    </collision>
  </link>
  <joint name="joint5" type="revolute">
    <origin rpy="1.5708 0 0" xyz="0.0775 -0.3425 0" />
    <parent link="link4" />
    <child link="link5" />
    <axis xyz="0 0 1" />
    <limit effort="30" lower="-6.283185307179586" upper="6.283185307179586" velocity="3.14" />
    <dynamics damping="5" friction="1" />
  </joint>
  <link name="link6">
    <inertial>
      <origin rpy="0 0 0" xyz="0.065 0.0334 0.0213" />
      <mass value="1.362" />
      <inertia ixx="0.0015156747169811323" ixy="-0.0005016271698113209" ixz="0.00030354611320754726" iyy="0.001956859924528302" iyz="0.0001516085886792453" izz="0.002431247094339623" />
    </inertial>
    <visual>
      <geometry>
        <mesh filename="link6.stl" />
      </geometry>
      <origin rpy="0 0 0" xyz="0 0 0" />
      <material name="White" />
    </visual>
    <collision>
      <geometry>
        <mesh filename="link6.stl" />
      </geometry>
      <origin rpy="0 0 0" xyz="0 0 0" />
    </collision>
  </link>
  <joint name="joint6" type="revolute">
    <origin rpy="1.5708 0 0" xyz="0 0 0" />
    <parent link="link5" />
    <child link="link6" />
    <axis xyz="0 0 1" />
    <limit effort="20" lower="-1.69297" upper="3.141592653589793" velocity="3.14" />
    <dynamics damping="2" friction="1" />
  </joint>
  <link name="link7">
    <inertial>
      <origin rpy="0 0 0" xyz="0.0 -0.00677 -0.01098" />
      <mass value="0.17" />
      <inertia ixx="9.3e-05" ixy="-0.0" ixz="-0.0" iyy="5.87e-05" iyz="-3.6e-06" izz="0.000132" />
    </inertial>
    <visual>
      <geometry>
        <mesh filename="link7.stl" />
      </geometry>
      <origin rpy="0 0 0" xyz="0 0 0" />
      <material name="Silver" />
    </visual>
    <collision>
      <geometry>
        <mesh filename="end_tool.stl" />
      </geometry>
      <origin rpy="0 0 0" xyz="0 0 0" />
    </collision>
  </link>
  <joint name="joint7" type="revolute">
    <origin rpy="-1.5708 0 0" xyz="0.076 0.097 0" />
    <parent link="link6" />
    <child link="link7" />
    <axis xyz="0 0 1" />
    <limit effort="20" lower="-6.283185307179586" upper="6.283185307179586" velocity="3.14" />
    <dynamics damping="2" friction="1" />
  </joint>
  <!-- <link name="${prefix}link_eef" />
    <joint name="${prefix}joint_eef" type="fixed">
      <origin xyz="0 0 0" rpy="0 0 0" />
      <parent link="${prefix}link7" />
      <child link="${prefix}link_eef" />
    </joint> -->
  <transmission name="tran1">
    <type>transmission_interface/SimpleTransmission</type>
    <joint name="joint1">
      <hardwareInterface>hardware_interface/PositionJointInterface</hardwareInterface>
    </joint>
    <actuator name="motor1">
      <hardwareInterface>hardware_interface/PositionJointInterface</hardwareInterface>
      <mechanicalReduction>100</mechanicalReduction>
    </actuator>
  </transmission>
  <transmission name="tran2">
    <type>transmission_interface/SimpleTransmission</type>
    <joint name="joint2">
      <hardwareInterface>hardware_interface/PositionJointInterface</hardwareInterface>
    </joint>
    <actuator name="motor2">
      <hardwareInterface>hardware_interface/PositionJointInterface</hardwareInterface>
      <mechanicalReduction>100</mechanicalReduction>
    </actuator>
  </transmission>
  <transmission name="tran3">
    <type>transmission_interface/SimpleTransmission</type>
    <joint name="joint3">
      <hardwareInterface>hardware_interface/PositionJointInterface</hardwareInterface>
    </joint>
    <actuator name="motor3">
      <hardwareInterface>hardware_interface/PositionJointInterface</hardwareInterface>
      <mechanicalReduction>100</mechanicalReduction>
    </actuator>
  </transmission>
  <transmission name="tran4">
    <type>transmission_interface/SimpleTransmission</type>
    <joint name="joint4">
      <hardwareInterface>hardware_interface/PositionJointInterface</hardwareInterface>
    </joint>
    <actuator name="motor4">
      <hardwareInterface>hardware_interface/PositionJointInterface</hardwareInterface>
      <mechanicalReduction>100</mechanicalReduction>
    </actuator>
  </transmission>
  <transmission name="tran5">
    <type>transmission_interface/SimpleTransmission</type>
    <joint name="joint5">
      <hardwareInterface>hardware_interface/PositionJointInterface</hardwareInterface>
    </joint>
    <actuator name="motor5">
      <hardwareInterface>hardware_interface/PositionJointInterface</hardwareInterface>
      <mechanicalReduction>100</mechanicalReduction>
    </actuator>
  </transmission>
  <transmission name="tran6">
    <type>transmission_interface/SimpleTransmission</type>
    <joint name="joint6">
      <hardwareInterface>hardware_interface/PositionJointInterface</hardwareInterface>
    </joint>
    <actuator name="motor6">
      <hardwareInterface>hardware_interface/PositionJointInterface</hardwareInterface>
      <mechanicalReduction>100</mechanicalReduction>
    </actuator>
  </transmission>
  <transmission name="tran7">
    <type>transmission_interface/SimpleTransmission</type>
    <joint name="joint7">
      <hardwareInterface>hardware_interface/PositionJointInterface</hardwareInterface>
    </joint>
    <actuator name="motor7">
      <hardwareInterface>hardware_interface/PositionJointInterface</hardwareInterface>
      <mechanicalReduction>100</mechanicalReduction>
    </actuator>
  </transmission>
  <gazebo reference="link_base">
    <selfCollide>true</selfCollide>
  </gazebo>
  <gazebo reference="link1">
    <selfCollide>true</selfCollide>
  </gazebo>
  <gazebo reference="link2">
    <selfCollide>true</selfCollide>
  </gazebo>
  <gazebo reference="link3">
    <selfCollide>true</selfCollide>
  </gazebo>
  <gazebo reference="link4">
    <selfCollide>true</selfCollide>
  </gazebo>
  <gazebo reference="link5">
    <selfCollide>true</selfCollide>
  </gazebo>
  <gazebo reference="link6">
    <selfCollide>true</selfCollide>
  </gazebo>
  <gazebo reference="link7">
    <selfCollide>true</selfCollide>
  </gazebo>
  <link name="link_eef" />
  <joint name="joint_eef" type="fixed">
    <origin rpy="0 0 0" xyz="0 0 0" />
    <parent link="link7" />
    <child link="link_eef" />
  </joint>
  <!-- Insert at the end of xarm_device_macro.xacro -->
</robot>